Workbook

Sheet Requirements
A1: Participant ID | B1: Original Requirement | C1: Translation | D1: User Story | E1: Domain | H1: Task 1 | I1: Task 2 | J1: Task 3
A2: Participant A | B2: The application shall provide accurate classification results with a minimum accuracy of 90% for binary classification problems, as evaluated by metrics such as F1-score, Recall, Precision, Accuracy or Mean squared error. | C2: The application shall provide accurate classification results with a minimum accuracy of 90% for binary classification problems, as evaluated by metrics such as F1-score, Recall, Precision, Accuracy or Mean squared error. | D2: As a biologist, I want the application to provide accurate classification results with a minimum accuracy of 90% for binary classification problems, as evaluated by metrics such as F1-score, Recall, Precision, Accuracy or Mean squared error, so that I can trust the model's results and make informed decisions based on the predictions. | E2: Biology | F2: Biology | G2: =IF(F2=Requirements!E2,"true","") -> true | H2: classification | K2: classification
A3: Participant A | B3: The application shall provide continuous monitoring and evaluation of the machine learning model's performance and accuracy, with feedback loops to improve the model over time. | C3: The application shall provide continuous monitoring and evaluation of the machine learning model's performance and accuracy, with feedback loops to improve the model over time. | D3: As a biologist, I want the application to provide continuous monitoring and evaluation of the machine learning model's performance and accuracy, with feedback loops to improve the model over time, so that I can adapt the model to changing biological conditions and improve its performance over time. | E3: Biology | F3: Biology | G3: =IF(F3=Requirements!E3,"true","") -> true | H3: spatio-temporal process learning | K3: classification | L3: clustering | M3: entity resolution | N3: representation learning | O3: sentiment analysis
A4: Participant A | B4: The application shall use interpretability techniques such as feature importance scores, decision trees, or saliency maps to understand the underlying biological mechanisms and validate the model's predictions. This can help build trust in the model's results and provide insights into the biological mechanisms underlying cancer subtypes. Furthermore high-dimensional genomic data can lead to spurious correlations and false discoveries, and in these cases interpretability can also help identify and remove them by identifying the genes and pathways that are driving the classification results. | C4: The application shall use interpretability techniques such as feature importance scores, decision trees, or saliency maps to understand the underlying biological mechanisms and validate the model's predictions. This can help build trust in the model's results and provide insights into the biological mechanisms underlying cancer subtypes. Furthermore high-dimensional genomic data can lead to spurious correlations and false discoveries, and in these cases interpretability can also help identify and remove them by identifying the genes and pathways that are driving the classification results. | D4: As a biologist, I want the application to use interpretability techniques such as feature importance scores, decision trees, or saliency maps to understand the underlying biological mechanisms and validate the model's predictions, so that I can gain insights into the biological mechanisms underlying cancer subtypes and identify the genes and pathways driving the classification results. | E4: Biology | F4: Biology | G4: =IF(F4=Requirements!E4,"true","") -> true | H4: classification | K4: anomaly detection
A5: Participant A | B5: The application must access to large-scale genomic datasets such as The Cancer Genome Atlas (TCGA) or International Cancer Genome Consortium (ICGC) to get the data necessary to perform this task. | C5: The application must access to large-scale genomic datasets such as The Cancer Genome Atlas (TCGA) or International Cancer Genome Consortium (ICGC) to get the data necessary to perform this task. | D5: As a biologist, I want to access large-scale genomic datasets such as The Cancer Genome Atlas (TCGA) or International Cancer Genome Consortium (ICGC) to get the data necessary to perform this task, so that I can analyze a diverse range of cancer types and gain a comprehensive understanding of cancer biology. | E5: Biology | F5: Biology | G5: =IF(F5=Requirements!E5,"true","") -> true | H5: clustering | K5: anomaly detection | L5: bias detection in language models | M5: bias detection in word embeddings | N5: classification | O5: entity resolution | P5: regression | Q5: sentiment analysis
A6: Participant A | B6: The application shall leverage cloud-based computing platforms and big data analytics to handle the high dimensionality of omics data and achieve scalable and efficient classification and clustering. | C6: The application shall leverage cloud-based computing platforms and big data analytics to handle the high dimensionality of omics data and achieve scalable and efficient classification and clustering. | D6: As a biologist, I want to leverage cloud-based computing platforms and big data analytics to handle the high dimensionality of omics data and achieve scalable and efficient classification and clustering, so that I can analyze large-scale genomic datasets and gain insights into the mechanisms underlying cancer subtypes. | E6: Biology | F6: Biology | G6: =IF(F6=Requirements!E6,"true","") -> true | H6: classification | I6: clustering | K6: advertising | L6: anomaly detection | M6: bias detection in language models | N6: bias detection in word embeddings | O6: classification | P6: clustering | Q6: data summarization | R6: districting | S6: entity resolution | T6: graph augmentation | U6: graph diffusion | V6: graph mining | W6: machine translation | X6: matching | Y6: pricing | Z6: ranking | AA6: regression | AB6: representation learning | AC6: resource allocation | AD6: risk assessment | AE6: sentiment analysis | AF6: spatio-temporal process learning | AG6: speech recognition | AH6: subset selection | AI6: task assignment
A7: Participant A | B7: The application shall use data preparation techniques such as sampling, feature selection, data cleaning, parallel processing, and dimensionality reduction to be able to process large-scale omics data. | C7: The application shall use data preparation techniques such as sampling, feature selection, data cleaning, parallel processing, and dimensionality reduction to be able to process large-scale omics data. | D7: As a biologist, I want to use data preparation techniques such as sampling, feature selection, data cleaning, parallel processing, and dimensionality reduction to be able to process large-scale omics data, so that I can optimize the performance of the machine learning models and reduce the impact of noise and spurious correlations. | E7: Biology | F7: Biology | G7: =IF(F7=Requirements!E7,"true","") -> true | H7: subset selection | K7: anomaly detection | L7: classification | M7: ranking | N7: regression | O7: representation learning | P7: sentiment analysis
A8: Participant A | B8: The application shall use supervised classification algorithms such as random forest, logistic regression, or deep learning neural networks to classify cancer subtypes based on gene expression profiles. | C8: The application shall use supervised classification algorithms such as random forest, logistic regression, or deep learning neural networks to classify cancer subtypes based on gene expression profiles. | D8: As a biologist, I want to use supervised classification algorithms such as random forest, logistic regression, or deep learning neural networks to classify cancer subtypes based on gene expression profiles, so that I can accurately identify different cancer subtypes and potentially develop targeted therapies. | E8: Biology | F8: Biology | G8: =IF(F8=Requirements!E8,"true","") -> true | H8: classification | K8: classification
A9: Participant A | B9: The application shall use unsupervised clustering algorithms such as K-means, hierarchical clustering, or principal component analysis to identify molecular subtypes of cancer based on genomic data. | C9: The application shall use unsupervised clustering algorithms such as K-means, hierarchical clustering, or principal component analysis to identify molecular subtypes of cancer based on genomic data. | D9: As a biologist, I want to use unsupervised clustering algorithms such as K-means, hierarchical clustering, or principal component analysis to identify molecular subtypes of cancer based on genomic data, so that I can gain insights into the underlying biological mechanisms driving cancer subtypes. | E9: Biology | F9: Biology | G9: =IF(F9=Requirements!E9,"true","") -> true | H9: clustering | K9: anomaly detection | L9: clustering | M9: representation learning
A10: Participant B | B10: Il sistema deve utilizzare algoritmi di ML per l'apprendimento di processi spazio-temporali | C10: The system must use ML algorithms for learning spatio-temporal processes. | D10: As a cardiologist, I want it to use ML algorithms for learning spatio-temporal processes so that it can continuously improve its accuracy in detecting and diagnosing cardiac diseases. | E10: Cardiology | F10: Cardiology | G10: =IF(F10=Requirements!E10,"true","") -> true | H10: spatio-temporal process learning | K10: anomaly detection | L10: bias detection in language models | M10: bias detection in word embeddings | N10: classification | O10: representation learning | P10: sentiment analysis
A11: Participant B | B11: Il sistema deve individuare pattern che possono indicare la presenza di malattie cardiache nei segnali Echo | C11: The system must identify patterns in Echo signals that may indicate the presence of cardiac disease. | D11: As a cardiologist, I want the system to identify patterns in Echo signals that may indicate the presence of cardiac disease so that I can diagnose and treat patients accurately. | E11: Cardiology | F11: Cardiology | G11: =IF(F11=Requirements!E11,"true","") -> true | H11: anomaly detection | K11: anomaly detection | L11: classification | M11: data summarization
A12: Participant B | B12: Il sistema deve processare segnali ECG | C12: The system must process ECG signals. | D12: As a cardiologist, I want the system to process ECG signals so that I can analyze the electrical activity of a patient's heart and detect any abnormalities. | E12: Cardiology | F12: Cardiology | G12: =IF(F12=Requirements!E12,"true","") -> true | H12: anomaly detection | K12: advertising | L12: anomaly detection | M12: bias detection in language models | N12: bias detection in word embeddings | O12: classification | P12: clustering | Q12: data summarization | R12: districting | S12: entity resolution | T12: graph augmentation | U12: graph diffusion | V12: graph mining | W12: machine translation | X12: matching | Y12: pricing | Z12: ranking | AA12: regression | AB12: representation learning | AC12: resource allocation | AD12: risk assessment | AE12: sentiment analysis | AF12: spatio-temporal process learning | AG12: speech recognition | AH12: subset selection | AI12: task assignment
A13: Participant B | B13: Il sistema deve processare segnali Echo | C13: The system must process Echo signals. | D13: As a cardiologist, I want the system to process Echo signals so that I can analyze the structure and function of a patient's heart and detect any abnormalities. | E13: Cardiology | F13: Cardiology | G13: =IF(F13=Requirements!E13,"true","") -> true | H13: anomaly detection | K13: other
A14: Participant B | B14: Il sistema deve riconoscere anomalie nei segnali ECG | C14: The system must recognize anomalies in ECG signals. | D14: As a cardiologist, I want the system to recognize anomalies in ECG signals so that I can identify any irregularities in a patient's heart activity and determine the appropriate treatment. | E14: Cardiology | F14: Cardiology | G14: =IF(F14=Requirements!E14,"true","") -> true | H14: anomaly detection | K14: anomaly detection | L14: bias detection in language models | M14: bias detection in word embeddings | N14: classification | O14: clustering | P14: entity resolution | Q14: machine translation | R14: matching | S14: ranking | T14: regression | U14: representation learning | V14: sentiment analysis | W14: speech recognition
A15: Participant B | B15: Il sistema deve riconoscere anomalie nei segnali Echo | C15: The system must recognize anomalies in Echo signals. | D15: As a cardiologist, I want the system to recognize anomalies in Echo signals so that I can identify any irregularities in a patient's heart structure or function and determine the appropriate treatment. | E15: Cardiology | F15: Cardiology | G15: =IF(F15=Requirements!E15,"true","") -> true | H15: anomaly detection | K15: anomaly detection | L15: bias detection in language models | M15: bias detection in word embeddings | N15: classification | O15: clustering | P15: entity resolution | Q15: machine translation | R15: matching | S15: ranking | T15: regression | U15: representation learning | V15: sentiment analysis | W15: speech recognition
A16: Participant M | B16: Il sistema deve utilizzare un algoritmo di filtraggio collaborativo per selezionare i direttori del casting per specifiche attività di selezione del casting in base alle capacità, all’esperienza e alle preferenze. | C16: The system must use a collaborative filtering algorithm to select casting directors for specific casting selection activities based on their abilities, experience, and preferences. | D16: As a casting director, I want the system to recommend me for specific casting selection activities based on my abilities, experience, and preferences, so that I can increase my chances of being selected for projects that match my expertise. | E16: Movies | F16: Medicine | G16: =IF(F16=Requirements!E16,"true","") | H16: matching | I16: classification | J16: clustering | K16: ranking
A17: Participant M | B17: Il sistema deve utilizzare una tecnica di filtraggio basato sui contenuti per analizzare le caratteristiche degli attori e delle attrici e assegnargli specifici ruoli. | C17: The system must use a content-based filtering technique to analyze the characteristics of actors and actresses and assign them specific roles. | D17: As a casting director, I want the system to use a content-based filtering technique to analyze the characteristics of actors and actresses and assign them specific roles, so that I can ensure that the right candidates are selected for the right roles. | E17: Movies | F17: Biology | G17: =IF(F17=Requirements!E17,"true","") | H17: subset selection | K17: other
A18: Participant M | B18: Il sistema deve utilizzare degli algoritmi per la classificazione delle competenze di un attore al fine di comprendere similarità tra i candidati ed affinità con un determinato ruolo. | C18: The system must use algorithms for the classification of an actor's skills to understand similarities between candidates and affinity with a particular role. | D18: As a casting director, I want the system to use algorithms for the classification of an actor's skills to understand similarities between candidates and affinity with a particular role, so that I can make better casting decisions and increase the chances of producing successful films. | E18: Movies | F18: Medicine | G18: =IF(F18=Requirements!E18,"true","") | H18: classification | K18: other
A19: Participant M | B19: Il sistema deve utilizzare la tecnica di analisi semantica (Latent Semantic Analysis) sui copioni di tutti i ruoli per estrarre dati significativi, confrontarli con le caratteristiche degli attori e utilizzarli per selezionare attori e attrici con maggior tasso di compatibilità. | C19: The system must use the technique of semantic analysis (Latent Semantic Analysis) on the scripts of all roles to extract significant data, compare them with the characteristics of actors and use them to select actors and actresses with a higher compatibility rate. | D19: As a casting director, I want the system to use the technique of semantic analysis (Latent Semantic Analysis) on the scripts of all roles to extract significant data, compare them with the characteristics of actors, and recommend actors and actresses with a higher compatibility rate, so that I can reduce the time and effort required to find suitable candidates. | E19: Movies | F19: Biology | G19: =IF(F19=Requirements!E19,"true","") | H19: subset selection | K19: classification | L19: regression
A20: Participant S | B20: Come sistema, voglio implementare algoritmi di regressione supervisionati, come la regressione random forest o la regressione gradient boosting, in modo da prevedere il numero di punti o di gol che un giocatore probabilmente segnerà in una determinata partita o stagione, in base a una serie di caratteristiche di input (come l'età, il regime di allenamento, gli infortuni precedenti e le condizioni ambientali). | C20: As a system, I want to implement supervised regression algorithms, such as random forest regression or gradient boosting regression, in order to predict the number of points or goals a player is likely to score in a given game or season, based on a series of input features (such as age, training regime, past injuries, and environmental conditions). | D20: As a coach or team manager, I want the system to predict the number of points or goals a player is likely to score in a given game or season, based on a series of input features such as age, training regime, past injuries, and environmental conditions, so that I can develop game strategies and improve team performance. | E20: Sport | F20: News | G20: =IF(F20=Requirements!E20,"true","") | H20: regression | K20: anomaly detection | L20: bias detection in language models | M20: bias detection in word embeddings | N20: classification | O20: clustering | P20: data summarization | Q20: graph mining | R20: machine translation | S20: matching | T20: ranking | U20: sentiment analysis
A21: Participant R | B21: As an ML-intensive application, I want to utilize advanced supervised regression algorithms, such as random forest regression or gradient boosting regression, to accurately predict athlete performance in complex and dynamic team sports scenarios. | C21: As an ML-intensive application, I want to utilize advanced supervised regression algorithms, such as random forest regression or gradient boosting regression, to accurately predict athlete performance in complex and dynamic team sports scenarios. | D21: As a coach, I want to use advanced supervised regression algorithms to accurately predict the performance of my athletes in complex and dynamic team sports scenarios, such as soccer or basketball. | E21: Sport | F21: Sport | G21: =IF(F21=Requirements!E21,"true","") -> true | H21: regression | K21: classification
A22: Participant Q | B22: Post Bias Identification: The system must recognize through Natural Language Processing algorithms the potential post bias | C22: Post Bias Identification: The system must recognize through Natural Language Processing algorithms the potential post bias | D22: As a cognitive psychologist, I want the system to recognize potential post bias through Natural Language Processing algorithms so that I can understand the cognitive processes underlying the interpretation of biased information by individuals in my research on cognitive biases. | E22: Psychology | F22: Biology | G22: =IF(F22=Requirements!E22,"true","") | H22: bias detection in language models | K22: anomaly detection | L22: bias detection in language models | M22: bias detection in word embeddings | N22: clustering | O22: data summarization | P22: graph mining | Q22: representation learning | R22: sentiment analysis
A23: Participant E | B23: The system must be able to handle large amounts of data, with no limits on number of files, to ensure system scalability. | C23: The system must be able to handle large amounts of data, with no limits on number of files, to ensure system scalability. | D23: As a computer vision researcher, I want the system to be able to handle large amounts of data, with no limits on the number of files, so that I can process and analyze large datasets in computer vision research. | E23: Computer Vision | F23: Computer Vision | G23: =IF(F23=Requirements!E23,"true","") -> true | H23: graph mining | K23: anomaly detection | L23: bias detection in language models | M23: classification | N23: entity resolution | O23: machine translation | P23: regression | Q23: representation learning | R23: sentiment analysis | S23: speech recognition
A24: Participant S | B24: Come sistema, voglio essere in grado di normalizzare i dati di input in modo da ridurre la varianza e garantire che i valori di input siano comparabili. | C24: As a system, I want to be able to normalize input data in order to reduce variance and ensure that input values are comparable. | D24: As a data analyst or researcher in the sports domain, I want the system to be able to normalize input data, in order to reduce variance and ensure that input values are comparable, so that the model's predictions are more accurate. | E24: Sport | F24: Biology | G24: =IF(F24=Requirements!E24,"true","") | H24: regression | K24: classification
A25: Participant S | B25: Come sistema voglio poter utilizzare piattaforme di elaborazione basate su cloud e big data analytics in modo che il modello possa gestire grandi quantità di dati e ottenere regressioni e classifiche scalabili ed efficienti. | C25: As a system, I want to be able to use cloud-based processing platforms and big data analytics so that the model can handle large amounts of data and obtain scalable and efficient regressions and classifications. | D25: As a data analyst or researcher in the sports domain, I want the system to be able to use cloud-based processing platforms and big data analytics, so that the model can handle large amounts of sports data and obtain scalable and efficient regressions and classifications, for making timely and accurate predictions. | E25: Sport | F25: Sport | G25: =IF(F25=Requirements!E25,"true","") -> true | H25: regression | I25: classification | K25: other
A26: Participant I | B26: Il sistema deve essere in grado di fornire un'analisi dettagliata sulla diffusione dell'informazione all'interno della rete sociale. | C26: The system must be capable of providing a detailed analysis of information diffusion within the social network. | D26: As a data analyst, I want the system to provide a detailed analysis of information diffusion within the social network so that I can understand how users are interacting with the system. | E26: Information Systems | F26: Information Systems | G26: =IF(F26=Requirements!E26,"true","") -> true | H26: anomaly detection | K26: other
A27: Participant H | B27: The system shall identify and handle any outliers or extreme values in the data that may affect the accuracy of price predictions | C27: The system shall identify and handle any outliers or extreme values in the data that may affect the accuracy of price predictions | D27: As a data scientist in the finance industry, I want the system to identify and handle any outliers or extreme values in the data that may affect the accuracy of price predictions, so that I can ensure the accuracy of the predictions. | E27: Finance & Marketing | F27: Biology | G27: =IF(F27=Requirements!E27,"true","") | H27: anomaly detection | K27: speech recognition
A28: Participant I | B28: Il sistema deve essere in grado di personalizzare messaggi pubblicitari per i nodi più influenti della rete sociale. | C28: The system must be capable of personalizing advertising messages for the most influential nodes in the social network. | D28: As a digital marketer, I want the system to personalize advertising messages for the most influential nodes in the social network so that I can increase the effectiveness of my campaigns. | E28: Information Systems | F28: Computer Networks | G28: =IF(F28=Requirements!E28,"true","") | H28: advertising | K28: anomaly detection | L28: bias detection in language models | M28: bias detection in word embeddings | N28: classification | O28: clustering | P28: data summarization | Q28: graph mining | R28: machine translation | S28: matching | T28: ranking | U28: sentiment analysis
A29: Participant G | B29: As an investor investing in company shares, I want to extract that company's information, so that I can extract useful metrics that can be used in price prediction of that share. | C29: As an investor investing in company shares, I want to extract that company's information, so that I can extract useful metrics that can be used in price prediction of that share. | D29: As a finance investor, I want to access a company's financial information to extract useful metrics for price prediction of that share. | E29: Finance & Marketing | F29: Finance & Marketing | G29: =IF(F29=Requirements!E29,"true","") -> true | H29: pricing | K29: anomaly detection | L29: bias detection in language models | M29: bias detection in word embeddings | N29: classification | O29: clustering | P29: machine translation | Q29: ranking | R29: regression | S29: sentiment analysis | T29: speech recognition
A30: Participant G | B30: As an investor, I want to know when a certain asset I hold is predicted to lose value in the near feature, so that I can assess if to keep it or not. | C30: As an investor, I want to know when a certain asset I hold is predicted to lose value in the near feature, so that I can assess if to keep it or not. | D30: As a finance investor, I want to receive alerts when a certain asset I hold is predicted to lose value in the near future to make an informed decision about whether to hold or sell it. | E30: Finance & Marketing | F30: Finance & Marketing | G30: =IF(F30=Requirements!E30,"true","") -> true | H30: regression | K30: bias detection in language models | L30: bias detection in word embeddings | M30: classification | N30: entity resolution | O30: machine translation | P30: regression | Q30: sentiment analysis | R30: speech recognition
A31: Participant G | B31: As an investor, I want to know people's opinion/sentiment on a financial investment product, so that I can make predictions on the product's value. | C31: As an investor, I want to know people's opinion/sentiment on a financial investment product, so that I can make predictions on the product's value. | D31: As a finance investor, I want to see the sentiment/opinion of other investors on a financial investment product to make informed predictions about the product's value. | E31: Finance & Marketing | F31: Finance & Marketing | G31: =IF(F31=Requirements!E31,"true","") -> true | H31: sentiment analysis | K31: anomaly detection | L31: bias detection in language models | M31: bias detection in word embeddings | N31: classification | O31: clustering | P31: data summarization | Q31: graph mining | R31: machine translation | S31: matching | T31: ranking | U31: sentiment analysis
A32: Participant J | B32: Classificazione dei documenti legali: il sistema deve essere in grado di classificare diversi tipi di documenti legali, come contratti, azioni legali, sentenze, tra gli altri, per facilitarne la gestione e la ricerca. | C32: Classification of legal documents: The system must be able to classify different types of legal documents, such as contracts, legal actions, judgments, among others, to facilitate their management and retrieval. | D32: As a law firm administrator, I want the system to classify different types of legal documents so that I can easily manage and retrieve them. | E32: Law | F32: Law | G32: =IF(F32=Requirements!E32,"true","") -> true | H32: classification | K32: anomaly detection | L32: bias detection in language models | M32: bias detection in word embeddings | N32: classification | O32: machine translation | P32: matching | Q32: ranking | R32: regression | S32: representation learning | T32: sentiment analysis | U32: speech recognition
A33: Participant J | B33: Riepilogo automatico dei documenti legali: il sistema deve essere in grado di generare riepiloghi accurati e concisi dei documenti legali, che consentano agli utenti di comprenderne rapidamente il contenuto. | C33: Automatic summarization of legal documents: The system must be able to generate accurate and concise summaries of legal documents, allowing users to quickly understand their content. | D33: As a law student, I want the system to generate accurate and concise summaries of legal documents so that I can quickly understand their content. | E33: Law | F33: Law | G33: =IF(F33=Requirements!E33,"true","") -> true | H33: data summarization | K33: data summarization
A34: Participant J | B34: Consulenza legale automatizzata: il sistema deve essere in grado di fornire raccomandazioni legali automatizzate, basate sull'interpretazione dei testi giuridici e della giurisprudenza esistente. | C34: Automated legal advice: The system must be able to provide automated legal recommendations based on the interpretation of legal texts and existing case law. | D34: As a legal advisor, I want the system to provide automated legal recommendations based on the interpretation of legal texts and existing case law so that I can provide timely and accurate legal advice to clients. | E34: Law | F34: Law | G34: =IF(F34=Requirements!E34,"true","") -> true | H34: representation learning | K34: anomaly detection | L34: bias detection in language models | M34: classification | N34: clustering | O34: data summarization | P34: graph augmentation | Q34: graph diffusion | R34: graph mining | S34: machine translation | T34: matching | U34: ranking | V34: representation learning | W34: sentiment analysis | X34: speech recognition | Y34: subset selection
A35: Participant K | B35: The system shall use sentiment analysis and representation learning techniques to identify and extract legal arguments and reasoning expressed in legal documents, enabling legal professionals to better understand the legal reasoning involved in specific cases or issues. | C35: The system shall use sentiment analysis and representation learning techniques to identify and extract legal arguments and reasoning expressed in legal documents, enabling legal professionals to better understand the legal reasoning involved in specific cases or issues. | D35: As a legal analyst, I want the system to identify and extract legal arguments and reasoning expressed in legal documents so that I can better understand the legal reasoning involved in specific cases or issues. | E35: Law | F35: Law | G35: =IF(F35=Requirements!E35,"true","") -> true | H35: representation learning | K35: bias detection in language models | L35: data summarization | M35: entity resolution | N35: graph mining | O35: machine translation | P35: sentiment analysis | Q35: speech recognition
A36: Participant J | B36: Analisi del sentiment: il sistema deve essere in grado di analizzare il tono e l'atteggiamento dei testi legali per determinare se si tratta di un documento positivo, negativo o neutro. | C36: Sentiment analysis: The system must be able to analyze the tone and attitude of legal texts to determine if the document is positive, negative, or neutral. | D36: As a legal analyst, I want the system to perform sentiment analysis on legal texts so that I can understand the tone and attitude of legal documents. | E36: Law | F36: Law | G36: =IF(F36=Requirements!E36,"true","") -> true | H36: sentiment analysis | K36: machine translation | L36: speech recognition
A37: Participant K | B37: The system shall use supervised representation learning techniques to create document embeddings that can capture the similarities and differences between legal documents on specific legal topics, in order to provide legal professionals with an overview of similar cases. | C37: The system shall use supervised representation learning techniques to create document embeddings that can capture the similarities and differences between legal documents on specific legal topics, in order to provide legal professionals with an overview of similar cases. | D37: As a legal expert, I want the system to create document embeddings that can capture the similarities and differences between legal documents on specific legal topics so that I can better understand similar cases. | E37: Law | F37: Law | G37: =IF(F37=Requirements!E37,"true","") -> true | H37: representation learning | K37: anomaly detection | L37: classification | M37: regression | N37: sentiment analysis | O37: speech recognition
A38: Participant J | B38: Identificazione di problemi legali: il sistema deve essere in grado di identificare problemi legali nei testi, come ambiguità, contraddizioni o mancanza di coerenza. | C38: Identification of legal issues: The system must be able to identify legal issues in texts, such as ambiguity, contradictions, or lack of coherence. | D38: As a legal expert, I want the system to identify legal issues in texts, such as ambiguity or contradictions, so that I can ensure the accuracy and coherence of legal documents. | E38: Law | F38: Law | G38: =IF(F38=Requirements!E38,"true","") -> true | H38: anomaly detection | K38: anomaly detection | L38: bias detection in language models | M38: bias detection in word embeddings | N38: classification | O38: clustering | P38: data summarization | Q38: graph mining | R38: machine translation | S38: matching | T38: ranking | U38: regression | V38: representation learning | W38: sentiment analysis | X38: speech recognition | Y38: subset selection
A39: Participant K | B39: The system shall use NLP and representation learning techniques to “neutralize” the sentiment of a legal document while preserving its meaning, in order to help legal professionals create neutral documents as part of creating document embeddings for downstream tasks. | C39: The system shall use NLP and representation learning techniques to “neutralize” the sentiment of a legal document while preserving its meaning, in order to help legal professionals create neutral documents as part of creating document embeddings for downstream tasks. | D39: As a legal professional, I want the system to "neutralize" the sentiment of a legal document while preserving its meaning so that I can create neutral documents for downstream tasks. | E39: Law | F39: Law | G39: =IF(F39=Requirements!E39,"true","") -> true | H39: sentiment analysis | K39: anomaly detection | L39: clustering | M39: representation learning
A40: Participant J | B40: Rilevamento del plagio nei documenti legali: il sistema deve essere in grado di rilevare il plagio nei testi legali, identificando somiglianze e coincidenze con altri documenti legali esistenti. | C40: Detection of plagiarism in legal documents: The system must be able to detect plagiarism in legal texts, identifying similarities and coincidences with other existing legal documents. | D40: As a legal professional, I want the system to detect plagiarism in legal texts, identifying similarities and coincidences with other existing legal documents, so that I can ensure the originality of legal documents. | E40: Law | F40: Law | G40: =IF(F40=Requirements!E40,"true","") -> true | H40: matching | K40: anomaly detection
...

Sheet Foglio1
A2: As a biologist, I want the application to provide accurate classification results with a minimum accuracy of 90% for binary classification problems, as evaluated by metrics such as F1-score, Recall, Precision, Accuracy or Mean squared error, so that I can trust the models results and make informed decisions based on the predictions.
A3: As a biologist, I want the application to provide continuous monitoring and evaluation of the machine learning models performance and accuracy, with feedback loops to improve the model over time, so that I can adapt the model to changing biological conditions and improve its performance over time.
A4: As a biologist, I want the application to use interpretability techniques such as feature importance scores, decision trees, or saliency maps to understand the underlying biological mechanisms and validate the models predictions, so that I can gain insights into the biological mechanisms underlying cancer subtypes and identify the genes and pathways driving the classification results.
A5: As a biologist, I want to access large-scale genomic datasets such as The Cancer Genome Atlas (TCGA) or International Cancer Genome Consortium (ICGC) to get the data necessary to perform this task, so that I can analyze a diverse range of cancer types and gain a comprehensive understanding of cancer biology.
A6: As a biologist, I want to leverage cloud-based computing platforms and big data analytics to handle the high dimensionality of omics data and achieve scalable and efficient classification and clustering, so that I can analyze large-scale genomic datasets and gain insights into the mechanisms underlying cancer subtypes.
A7: As a biologist, I want to use data preparation techniques such as sampling, feature selection, data cleaning, parallel processing, and dimensionality reduction to be able to process large-scale omics data, so that I can optimize the performance of the machine learning models and reduce the impact of noise and spurious correlations.
A8: As a biologist, I want to use supervised classification algorithms such as random forest, logistic regression, or deep learning neural networks to classify cancer subtypes based on gene expression profiles, so that I can accurately identify different cancer subtypes and potentially develop targeted therapies.
A9: As a biologist, I want to use unsupervised clustering algorithms such as K-means, hierarchical clustering, or principal component analysis to identify molecular subtypes of cancer based on genomic data, so that I can gain insights into the underlying biological mechanisms driving cancer subtypes.
A10: As a cardiologist, I want it to use ML algorithms for learning spatio-temporal processes so that it can continuously improve its accuracy in detecting and diagnosing cardiac diseases.
A11: As a cardiologist, I want the system to identify patterns in Echo signals that may indicate the presence of cardiac disease so that I can diagnose and treat patients accurately.
A12: As a cardiologist, I want the system to process ECG signals so that I can analyze the electrical activity of a patients heart and detect any abnormalities.
A13: As a cardiologist, I want the system to process Echo signals so that I can analyze the structure and function of a patients heart and detect any abnormalities.
... A120: As an economic analyst, I want the system to extract and collect data from large-scale advertising sources (e.g. online ads, billboards, TV commercials), so that I can analyze and understand the trends and patterns in the advertising industry.
