Workbook

Sheet Sample
B1: User Story | C1: Domain | D1: Machine Learning Keyword
A2: Survey 1 | B2: As an educator, I want to use abstractive summarization to analyze and summarize research on effective teaching methods, so that I can apply the latest research to my own teaching practice. | C2: Education | D2: Abstractive summarization
A3: Survey 1 | B3: As a literary critic or scholar, I want to use extreme learning machine to analyze literary works and predict literary trends and patterns, so that I can provide better analysis and criticism of literary works. | C3: Literature | D3: extreme learning machine
A4: Survey 1 | B4: As an urban planner, I want to use preference learning to identify which urban design elements (e.g., green space, public art) are most preferred by residents in a specific neighborhood. | C4: Urban Studies | D4: preference learning
A5: Survey 1 | B5: As a movie studio, I want to use similarity learning algorithms to analyze audience data and identify similarities between different audience segments, to better understand audience needs and inform casting and marketing decisions. | C5: Movies | D5: similarity learning
A6: Survey 1 | B6: As a demographer, I want to use keyword spotting to identify specific demographic data in large datasets, so that I can better understand population trends and make predictions. | C6: Demography | D6: keyword spotting
A7: Survey 2 | B7: As a sports analyst, I want to use AdaBoost to predict game outcomes and identify key factors that influence team performance to improve sports strategies. | C7: Sport | D7: adaboost
A8: Survey 2 | B8: As a healthcare provider, I want to use learning from demonstration to analyze patient data and identify patterns that may indicate potential health issues, allowing for earlier detection and improved patient outcomes. | C8: Health | D8: learning from demonstration
A9: Survey 2 | B9: As a plant scientist, I want to use a recommendation system to suggest the best crop varieties and cultivation practices for specific environmental conditions and market demand. | C9: Plant Science | D9: recommendation system
A10: Survey 2 | B10: As a sociologist, I want to use multinomial logistic regression to predict social trends and patterns based on social phenomena and behaviors to improve social analysis and understanding. | C10: Sociology | D10: multinomial logistic regression
A11: Survey 2 | B11: As an economist, I want to use BLSTM networks to forecast economic trends and predict market behavior, so that I can help businesses and organizations make informed decisions. | C11: Economics | D11: Bidirectional Long Short-Term Memory
A12: Survey 3 | B12: As a botanist, I want to use sentence generation to automatically generate descriptions of plant species based on their characteristics, to improve our understanding of plant taxonomy and inform botanical research. | C12: Plant Science | D12: sentence generation
A13: Survey 3 | B13: As a nephrologist, I want to use multiple instance learning to identify groups of patients with similar kidney disease characteristics and risk factors based on various patient data sources to improve disease prevention and treatment. | C13: Nephrology | D13: multiple instance learning
... A107: Survey 22 | B107: As a transportation company, I want to use convolutional neural networks to develop image recognition models that can identify and track vehicles, pedestrians, and road signs in real-time video footage. | C107: Transportation | D107: convolutional neural network
A108: =A107 -> Survey 22 | B108: As a demographer, I want to use extreme learning machine to analyze census data and predict population trends and patterns, so that I can make informed policy recommendations. | C108: Demography | D108: extreme learning machine
A109: =A108 -> Survey 22 | B109: As a linguist, I want to summarize linguistic research and reports to quickly identify relevant information for linguistic research and analysis. | C109: Linguistics | D109: text summarization
A110: =A109 -> Survey 22 | B110: As a medical researcher, I want to use n-grams to analyze patterns in medical research publications and clinical trial data, so that I can better understand the state of medical research in specific areas and identify gaps in knowledge. | C110: Medicine | D110: n-grams
A111: =A110 -> Survey 22 | B111: As a movie producer, I want to use action model learning to predict box office success and audience reception, so that I can create more successful movies and maximize profits. | C111: Movies | D111: action model learning
A112: Survey 23 | B112: As a literature scholar, I want to use perceptron to classify literary works based on their genre and style to analyze literary movements and trends. | C112: Literature | D112: perceptron
A113: =A112 -> Survey 23 | B113: As a social network researcher, I want to use voice recognition to analyze audio recordings from social media platforms and identify patterns in language use and communication behaviors, so that I can better understand how people interact with each other online and develop more accurate models of online communication. | C113: Social Networks | D113: voice recognition
A114: =A113 -> Survey 23 | B114: As a nephrologist , I want to use a voice command device to access patient records and control medical equipment so that I can more efficiently and accurately diagnose and treat kidney diseases. | C114: Nephrology | D114: voice command device
A115: =A114 -> Survey 23 | B115: As an educator, I want to use multinomial classification to classify student data based on their performance and characteristics to provide effective personalized learning opportunities. | C115: Education | D115: multinomial classification
A116: =A115 -> Survey 23 | B116: As a transportation analyst, I want to utilize Bayesian learning to analyze traffic patterns and identify the most likely causes of congestion, so that I can recommend the most effective solutions for improving traffic flow. | C116: Transportation | D116: Bayesian Learning
A117: Survey 24 | B117: As a literary scholar, I want to use conditional random fields to predict literary trends and reception based on literary and environmental variables, such as identifying clusters of literary works with high levels of intertextual references or predicting literary movements, so that we can better understand patterns of literary production and reception. | C117: Literature | D117: conditional random field
A118: =A117 -> Survey 24 | B118: As a lawyer, I want to use robot learning to analyze large amounts of legal data, so that I can identify trends and patterns in court decisions and better advise my clients. | C118: Law | D118: robot learning
A119: =A118 -> Survey 24 | B119: As a political scientist, I want to use unsupervised learning to identify patterns in voting data and study the relationship between demographic characteristics and election outcomes. | C119: Political Science | D119: unsupervised learning
A120: =A119 -> Survey 24 | B120: As a social network researcher, I want to use maximum entropy modeling to identify the most influential nodes in a given social network. | C120: Social Networks | D120: maximum entropy modeling
A121: =A120 -> Survey 24 | B121: As a sports organization, I want to use a recommender engine to suggest personalized sports news and content to each fan, based on their interests, team preferences, and social network, using machine learning algorithms. | C121: Sport | D121: recommender engine
A122: Survey 25 | B122: As a dermatologist, I want to use hidden Markov models to analyze the skin lesion patterns and evolution based on the time-series data of dermatological images and patient records to improve the accuracy and efficiency of skin disease diagnosis and treatment. | C122: Dermatology | D122: hidden markov model
A123: =A122 -> Survey 25 | B123: As a dermatologist, I want to use mention detection to identify the most frequently mentioned skin conditions or symptoms in a given medical literature or social media dataset. | C123: Dermatology | D123: mention detection
A124: =A123 -> Survey 25 | B124: As a psychologist, I want to use reinforcement learning to develop better models of mental health treatment and improve patient outcomes. | C124: Psychology | D124: reinforcement learning
A125: =A124 -> Survey 25 | B125: As a dermatologist, I want to utilize document embedding to represent medical images as vectors of skin condition-specific features, so that I can more easily diagnose skin diseases and develop targeted treatment plans. | C125: Dermatology | D125: document embedding
A126: =A125 -> Survey 25 | B126: As a computational biologist, I want to use word embedding techniques to analyze large sets of genomic data and identify common patterns of gene expression, so that I can better understand the underlying regulatory mechanisms that control cell function. | C126: Biology | D126: Word Embedding
A127: Survey 26 | B127: As an information systems analyst, I want to identify multiword expressions in user search queries to improve search engine functionality. | C127: Information Systems | D127: multiword expressions
A128: =A127 -> Survey 26 | B128: As a neuroscientist, I want to use deep networks to analyze large sets of brain imaging data and identify patterns of neural activity associated with different mental states, so that I can better understand the neural basis of human consciousness. | C128: Biology | D128: deep network
A129: =A128 -> Survey 26 | B129: As an urban planner, I want to use multifactor dimensionality reduction to identify the combination of demographic, socio-economic, and land use factors that contribute to urban growth and development, so that I can make more informed decisions about land use and urban planning. | C129: Urban Studies | D129: multifactor dimensionality reduction
A130: =A129 -> Survey 26 | B130: As a sports analyst, I want to use fuzzy neural networks to predict athletic performance and outcomes based on large datasets of athlete data, so that I can better analyze and understand sports performance. | C130: Sport | D130: fuzzy neural network
A131: =A130 -> Survey 26 | B131: As a transportation engineer, I want to use Echo State Networks to predict traffic flow and congestion patterns based on historical sensor data from highways and urban roads, as well as real-time data from connected vehicles and smart infrastructure. | C131: Transportation | D131: echo state network
A132: Survey 27 | B132: As a bioinformatics researcher, I want to use random forest algorithms to analyze large sets of genomic data and identify patterns of gene expression, so that I can better understand the underlying biological mechanisms that control cell function. | C132: Biology | D132: random forest
A133: =A132 -> Survey 27 | B133: As a network administrator, I want to use inductive logic learning to identify patterns in network traffic data, in order to improve network security and performance. | C133: Computer Networks | D133: inductive logic learning
...

Sheet Results
A1: Survey | B1: Participant | C1: User Story | D1: Domain | E1: Machine Learning Keyword | F1: Comprehensibility | G1: Actionability | H1: Realism | I1: Different format [Yes/No] | J1: Alternative
A2: Survey 17 | B2: Participant 11 | C2: As a filmmaker, I want to use music information retrieval to analyze how music is used in movies, so that I can better understand how music contributes to the emotional impact of films and make more effective use of music in my own films. | D2: Movies | E2: music information retrieval | F2: 5 | G2: 5 | H2: 5 | I2: Yes | J2: " As a filmmaker, I want to use music information retrieval to analyze how music is used in movies, so that I can better understand how music is used in the films industry and make more effective use of music in my own films. "
A3: Survey 12 | B3: Participant 11 | C3: As a medical researcher, I want to use explicit semantic analysis to analyze medical literature and identify relevant research on diseases and treatments, so that I can develop better therapies and treatments. | D3: Medicine | E3: explicit semantic analysis | F3: 5 | G3: 4 | H3: 3 | I3: Yes | J3: " As a medical researcher, I want to use explicit semantic analysis to analyze recent medical literature and identify relevant research on diseases and treatments, so that I can develop better therapies and treatments. "
A4: =A3 -> Survey 12 | B4: Participant 11 | C4: As a news editor, I want to use synaptic weight algorithms to predict which news stories are likely to be most popular with readers and optimize editorial content accordingly. | D4: News | E4: synaptic weight | F4: 5 | G4: 5 | H4: 5 | I4: Yes | J4: " As a news editor, I want to use weight algorithms to predict which news stories are likely to be most popular with readers and optimize editorial content accordingly."
A5: =A4 -> Survey 12 | B5: Participant 37 | C5: As a medical researcher, I want to use mixture models to analyze patient data and medical research findings and identify different types of diseases and their potential causes, in order to develop more effective treatment plans and preventive strategies. | D5: Medicine | E5: mixture model | F5: 3 | G5: 4 | H5: 3 | I5: Yes | J5: "As a medical researcher, I want to use mixture models for in-depth analysis of patient data and medical research findings. By identifying distinct disease types and their potential underlying causes, I aim to develop more effective and personalized treatment plans and preventive strategies."
A6: Survey 34 | B6: Participant 13 | C6: As an IT professional, I want to use evolutionary robotics to optimize network architecture and improve system performance. | D6: Information Systems | E6: evolutionary robotics | F6: 5 | G6: 4 | H6: 3 | I6: Yes | J6: "As an IT professional, I want to use x or y technology to optimize network...." should be more specific
A7: =A6 -> Survey 34 | B7: Participant 18 | C7: As a computer vision researcher, I need to use a deep belief network to identify patterns in visual data and predict object recognition and segmentation. | D7: Computer Vision | E7: deep belief network | F7: 4 | G7: 3 | H7: 4 | I7: Yes | J7: As a computer vision researcher, I want to leverage deep belief networks to analyze visual data, identify intricate patterns, and achieve high-performance object recognition and segmentation.
A8: =A7 -> Survey 34 | B8: Participant 38 | C8: As a demographer, I want to use neural machine translation to translate and analyze demographic data from different countries and regions, so that I can better understand population trends and migration patterns. | D8: Demography | E8: neural machine translation | F8: 4 | G8: 3 | H8: 4 | I8: Yes | J8: As a demographer, I aim to develop a neural machine translation model that can accurately translate and analyze demographic data from diverse countries and regions. The objective is to gain deeper insights into population trends, migration patterns, and demographic changes across different geographic areas. By effectively utilizing neural machine translation, I can enhance the comparability of demographic data, leading to more comprehensive and informed demographic analyses.
A9: Survey 45 | B9: Participant 38 | C9: As a dermatologist, I want to use neural cryptography to secure and protect confidential medical data related to skin diseases and conditions, so that I can maintain patient privacy and prevent data breaches. | D9: Dermatology | E9: neural cryptography | F9: 4 | G9: 3 | H9: 4 | I9: Yes | J9: As a dermatologist, I want to implement a neural cryptography-based system that ensures the secure storage and transmission of confidential medical data related to skin diseases and conditions. This will help maintain patient privacy, prevent data breaches, and comply with data protection regulations.
A10: =A9 -> Survey 45 | B10: Participant 18 | C10: As a film critic, I want to use latent Dirichlet allocation to identify latent topics in movie reviews related to cinematography, so that I can better understand the critical landscape and identify potential areas for further analysis. | D10: Movies | E10: latent dirichlet allocation | F10: 4 | G10: 3 | H10: 4 | I10: Yes | J10: As a film critic, I want to employ latent Dirichlet allocation to uncover underlying topics and themes in movie reviews, specifically focusing on aspects related to cinematography. By doing so, I aim to gain deeper insights into the critical reception of films and identify potential avenues for further investigation.
A11: =A10 -> Survey 45 | B11: Participant 38 | C11: As a journalist, I want to use stochastic game theory to model the behavior of different news outlets to better understand the impact of different editorial policies on news coverage. | D11: News | E11: stochastic game | F11: 4 | G11: 3 | H11: 4 | I11: Yes | J11: As a journalist, I want to develop a stochastic game theory-based model that analyzes the behavior of different news outlets. The goal is to gain insights into how their editorial policies influence news coverage and the public's perception. By understanding these dynamics, I can better inform my reporting and contribute to a more informed public discourse.
A12: Survey 1 | B12: Participant 2 | C12: As a literary critic or scholar, I want to use extreme learning machine to analyze literary works and predict literary trends and patterns, so that I can provide better analysis and criticism of literary works. | D12: Literature | E12: extreme learning machine | F12: 2 | G12: 2 | H12: 1 | I12: Yes | J12: As a literary critic or scholar, I want to use machine learning to analyze literary works and predict literary trends and patterns, so that I can provide better analysis and criticism of literary works.
A13: =A12 -> Survey 1 | B13: Participant 18 | C13: As a nephrologist, I want to use lexical entailment to identify and analyze the relationships between different kidney-related concepts. | D13: Nephrology | E13: lexical entailment | F13: 4 | G13: 3 | H13: 4 | I13: Yes | J13: As a nephrologist, I want to leverage lexical entailment techniques to automatically discover and explore the underlying semantic relationships between various medical terms and concepts related to kidney diseases and treatments.
A14: =A13 -> Survey 1 | B14: Participant 38 | C14: As a pediatrician, I want to use keyphrase extraction to automatically extract important terms and phrases from patient medical records and research articles, so that I can better understand pediatric health trends and provide more effective care. | D14: Pediatrics | E14: keyphrase extraction | F14: 5 | G14: 4 | H14: 5 | I14: Yes | J14: As a pediatrician, I aim to implement keyphrase extraction techniques to automatically identify and extract crucial terms and phrases from patient medical records and relevant research articles. By leveraging keyphrase extraction, I intend to gain deeper insights into pediatric health trends and improve the effectiveness of medical care for my young patients.
A15: =A14 -> Survey 1 | B15: Participant 38 | C15: As a radiologist - I want to use relational learning to develop more accurate medical image analysis models and better understand the relationships between different health variables. | D15: Radiology | E15: relational learning | F15: 4 | G15: 4 | H15: 5 | I15: Yes | J15: As a radiologist, I aim to implement relational learning techniques to enhance the accuracy of medical image analysis models and gain deeper insights into the relationships between various health variables. By leveraging relational learning, I intend to improve diagnostic precision and contribute to a more comprehensive understanding of medical imaging data for better patient care and treatment outcomes.
A16: =A15 -> Survey 1 | B16: Participant 22 | C16: As a sports analyst, I want to use computational argumentation to analyze and evaluate the effectiveness of different strategies used in sports. | D16: Sport | E16: computational argumentation | F16: 3 | G16: 2 | H16: 1 | I16: Yes | J16: As a sports analyst, I want to use computation argumentation to analyze and evaluate X value, X value, X value in strategies used in sports, in order to evaluate the effectiveness of each strategy.
A17: Survey 3 | B17: Participant 6 | C17: As an endocrinologist, I want to use part-of-speech tagging to analyze patient records to identify the most commonly used words and phrases related to hormone levels and disorders. | D17: Endocrinology | E17: part-of-speech | F17: 3 | G17: 2 | H17: 2 | I17: Yes | J17: As an endocrinologist, I can to use part-of-speech tagging to analyze patientr ecords to identify the most commonly used words and phrases related to hormone levels and disorders.This will help me to improve the overall treatment approach for my patients.
A18: Survey 16 | B18: Participant 9 | C18: As a linguist, I want to use supervised deep networks to predict and analyze language acquisition and use based on linguistic data. | D18: Linguistics | E18: supervised deep networks | F18: 4 | G18: 3 | H18: 2 | I18: Yes | J18: Be a bit more accurate.
A19: Survey 5 | B19: Participant 9 | C19: As a computer vision researcher, I want to use natural language generation to generate reports on image and video processing algorithms, so that I can more easily communicate my findings to other researchers and the wider computer vision community. | D19: Computer Vision | E19: natural language generation | F19: 4 | G19: 3 | H19: 3 | I19: Yes | J19: Be more realistic regarding what it is that he wants to change
A20: =A19 -> Survey 5 | B20: Participant 14 | C20: As a healthcare provider, I want to use summarization to quickly analyze patient records and medical literature to inform my treatment decisions. | D20: Health | E20: summarization | F20: 4 | G20: 2 | H20: 3 | I20: Yes | J20: Categorizer the treatments for all the type for obtain better results
A21: =A20 -> Survey 5 | B21: Participant 44 | C21: As a librarian, I want to use canonical correlation analysis to identify the relationship between book circulation patterns and patron demographics. | D21: Library | E21: canonical correlation analysis | F21: 3 | G21: 5 | H21: 4 | I21: Yes | J21: Create library cards that patrons would use to borrow books. Link demographics of patrons to the library.
A22: =A21 -> Survey 5 | B22: Participant 14 | C22: As a computer vision researcher, I want to use machine learning models to analyze imbalanced datasets of images and video, in order to develop more accurate and efficient computer vision algorithms for a wide range of applications. | D22: Computer Vision | E22: imbalanced dataset | F22: 5 | G22: 4 | H22: 4 | I22: Yes | J22: Explain and use CNN for the classification
A23: Survey 10 | B23: Participant 14 | C23: As a sports analyst, I want to use neocognitron to recognize and classify visual content in sports events, so that I can analyze and compare different games and players. | D23: Sport | E23: neocognitron | F23: 4 | G23: 2 | H23: 3 | I23: Yes | J23: Explain more exactly the type of label you need to analyzer
A24: Survey 21 | B24: Participant 14 | C24: As a librarian, I want to use structured output to predict the optimal placement of a particular book based on various factors such as genre, author popularity, and borrowing history. | D24: Library | E24: structured output | F24: 1 | G24: 3 | H24: 1 | I24: Yes | J24: Explain more of the problem and general more the problem
A25: Survey 24 | B25: Participant 14 | C25: As a literary scholar, I want to use conditional random fields to predict literary trends and reception based on literary and environmental variables, such as identifying clusters of literary works with high levels of intertextual references or predicting literary movements, so that we can better understand patterns of literary production and reception. | D25: Literature | E25: conditional random field | F25: 1 | G25: 3 | H25: 4 | I25: Yes | J25: Explain the type of values for work used much literary bur not say nothing about the problem
A26: Survey 60 | B26: Participant 14 | C26: As a social worker, I want to use NooJ to analyze social policy data and identify patterns in social issues, so that we can better understand the broader social context in which we work. | D26: Social Work | E26: nooj | F26: 2 | G26: 1 | H26: 1 | I26: Yes | J26: He need reorganizer the problem for identify the data for solved the problem is very general and complicated for obtain results
A27: Survey 3 | B27: Participant 5 | C27: As an endocrinologist, I want to use part-of-speech tagging to analyze patient records to identify the most commonly used words and phrases related to hormone levels and disorders. | D27: Endocrinology | E27: part-of-speech | F27: 2 | G27: 3 | H27: 2 | I27: No | J27: I did not understand the relationship between speech and hormones
A28: Survey 18 | B28: Participant 5 | C28: As an endocrinologist, I want to use speech recognition to transcribe patient histories and medical notes, which can help me to easily reference the content and improve patient care efficiency. | D28: Endocrinology | E28: speech recognition | F28: 4 | G28: 5 | H28: 4 | I28: Yes | J28: I did not understand the relationship between speech recognition and hormones
A29: =A28 -> Survey 18 | B29: Participant 5 | C29: As a dermatologist, I want to use word-sense disambiguation to identify the correct meaning of medical terms related to skin health. | D29: Dermatology | E29: word-sense disambiguation | F29: 2 | G29: 1 | H29: 1 | I29: No | J29: I did not understand the relationship between word-sense and skin health
A30: Survey 6 | B30: Participant 5 | C30: As a network administrator, I want to use voice activity detection to analyze network traffic and identify patterns in speech and language use so that I can detect and prevent security threats that involve voice and audio data. | D30: Computer Networks | E30: voice activity detection | F30: 2 | G30: 3 | H30: 1 | I30: No | J30: I don't understand the relation between network traffic and patterns in speech and language
A31: Survey 16 | B31: Participant 9 | C31: As an IT professional, I want to use convolutional neural networks to develop computer vision models that can detect and analyze anomalies in network traffic, enabling more effective network security. | D31: Information Systems | E31: convolutional neural network | F31: 1 | G31: 2 | H31: 1 | I31: Yes | J31: I personally don't think in the form of health that this would be more beneficial
A32: Survey 10 | B32: Participant 15 | C32: As a linguist, I want to use evolutionary robotics to simulate language evolution and study the origins of language. | D32: Linguistics | E32: evolutionary robotics | F32: 4 | G32: 3 | H32: 4 | I32: Yes | J32: I think the definition of language can be troublesome here, and which language it is talking about.
A33: =A32 -> Survey 10 | B33: Participant 9 | C33: As a political scientist, I want to use stemming algorithms to analyze political speeches and identify related topics and concepts, so that I can better understand and predict political trends and patterns. | D33: Political Science | E33: stemming | F33: 2 | G33: 3 | H33: 2 | I33: Yes | J33: In some way this is unrealistic
A34: =A33 -> Survey 10 | B34: Participant 14 | C34: As a literary scholar, I want to use ontology to develop a comprehensive taxonomy of literary genres and styles, so that we can better understand and analyze the diversity of literature. | D34: Literature | E34: ontology | F34: 5 | G34: 2 | H34: 2 | I34: Yes | J34: Need more explain that the type of data need for obtain results
A35: Survey 57 | B35: Participant 14 | C35: As a social media marketer, I want to use sentence generation to automatically generate social media posts and advertisements, to improve engagement with target audiences and enhance brand awareness. | D35: Social Media | E35: sentence generation | F35: 4 | G35: 2 | H35: 4 | I35: Yes | J35: Need more explanation of the type of info that used for generate the answer
A36: =A35 -> Survey 57 | B36: Participant 14 | C36: As a social network researcher, I want to use maximum entropy modeling to identify the most influential nodes in a given social network. | D36: Social Networks | E36: maximum entropy modeling | F36: 2 | G36: 4 | H36: 3 | I36: Yes | J36: Need to explain more the problem
A37: Survey 68 | B37: Participant 14 | C37: As a network analyst, I want to use Kohonen neural networks to identify patterns in social network data, so that I can better understand network behavior and develop more effective network analysis strategies. | D37: Social Networks | E37: kohonen neural network | F37: 2 | G37: 3 | H37: 2 | I37: Yes | J37: Need to explain more the problem and the data for used
A38: Survey 7 | B38: Participant 9 | C38: As a public health researcher, I want to use binary classification models to predict disease outbreaks and track the spread of infectious diseases, so that I can better understand and respond to public health threats. | D38: Health | E38: binary classification | F38: 3 | G38: 4 | H38: 3 | I38: Yes | J38: Provide more details as to how you are going to by doing this, or will this take place in the form of human test-subjects?
A39: Survey 10 | B39: Participant 14 | C39: As a sociologist, I want to use a learning-based method to analyze social trends and predict changes in societal behavior, so that I can provide insights to policymakers and help shape public policy. | D39: Sociology | E39: learning-based method | F39: 4 | G39: 2 | H39: 1 | I39: Yes | J39: The idea need be more general explain exactly the type of data is very general the info
A40: Survey 5 | B40: Participant 9 | C40: As a network engineer, I want to use sentence generation to automatically generate network documentation and support materials, to improve network efficiency and reduce support requests. | D40: Computer Networks | E40: sentence generation | F40: 4 | G40: 2 | H40: 3 | I40: Yes | J40: there are permissions to adhere to when completing these sentence generation
...

Sheet Short Statistics
A1: Survey | B1: Responses
A2: Survey 1 | B2: =countif(Results!A:A,A2) -> 14 | F2: 1 | G2: 2 | H2: 3 | I2: 4 | J2: 5
A3: Survey 2 | B3: =countif(Results!A:A,A3) -> 10 | E3: Comprehensibility | F3: =countif(Results!$F:$F,$F$2) -> 11 | G3: =countif(Results!$F:$F,G2) -> 45 | H3: =countif(Results!$F:$F,H2) -> 112 | I3: =countif(Results!$F:$F,I2) -> 315 | J3: =countif(Results!$F:$F,J2) -> 267 | K3: =SUM(F3:J3) -> 750
A4: Survey 3 | B4: =countif(Results!A:A,A4) -> 10 | E4: Actionability | F4: =countif(Results!$G:$G,F$2) -> 11 | G4: =countif(Results!$G:$G,G$2) -> 64 | H4: =countif(Results!$G:$G,H$2) -> 173 | I4: =countif(Results!$G:$G,I$2) -> 307 | J4: =countif(Results!$G:$G,J$2) -> 195 | K4: =SUM(F4:J4) -> 750
A5: Survey 4 | B5: =countif(Results!A:A,A5) -> 10 | E5: Realism | F5: =countif(Results!$H:$H,F$2) -> 30 | G5: =countif(Results!$H:$H,G$2) -> 82 | H5: =countif(Results!$H:$H,H$2) -> 164 | I5: =countif(Results!$H:$H,I$2) -> 257 | J5: =countif(Results!$H:$H,J$2) -> 217 | K5: =SUM(F5:J5) -> 750
A6: Survey 5 | B6: =countif(Results!A:A,A6) -> 13
A7: Survey 6 | B7: =countif(Results!A:A,A7) -> 10
A8: Survey 7 | B8: =countif(Results!A:A,A8) -> 10
A9: Survey 8 | B9: =countif(Results!A:A,A9) -> 14
A10: Survey 9 | B10: =countif(Results!A:A,A10) -> 10
A11: Survey 10 | B11: =countif(Results!A:A,A11) -> 12
A12: Survey 11 | B12: =countif(Results!A:A,A12) -> 10
A13: Survey 12 | B13: =countif(Results!A:A,A13) -> 12
A14: Survey 13 | B14: =countif(Results!A:A,A14) -> 10
A15: Survey 14 | B15: =countif(Results!A:A,A15) -> 10
A16: Survey 15 | B16: =countif(Results!A:A,A16) -> 10
A17: Survey 16 | B17: =countif(Results!A:A,A17) -> 10
... A76: Survey 75 | B76: =countif(Results!A:A,A76) -> 10
